Traceback (most recent call last):
  File "Run_rebuild_Thornton_AR_MR.py", line 28, in <module>
    MG94_tau = ReCodonGeneconv( newicktree, alignment_file, paralog, Model = 'MG94', Force = Force, clock = None, save_path = './test/save/')
  File "/home3/jxiong7/IGCexpansion/IGCexpansion/CodonGeneconv.py", line 97, in __init__
    self.initialize_parameters()
  File "/home3/jxiong7/IGCexpansion/IGCexpansion/CodonGeneconv.py", line 102, in initialize_parameters
    self.get_data()
  File "/home3/jxiong7/IGCexpansion/IGCexpansion/CodonGeneconv.py", line 126, in get_data
    seq_dict = SeqIO.to_dict(SeqIO.parse( self.seqloc, "fasta" ))
  File "/usr/local/lib/python2.7/dist-packages/Bio/SeqIO/__init__.py", line 731, in to_dict
    for record in sequences:
  File "/usr/local/lib/python2.7/dist-packages/Bio/SeqIO/__init__.py", line 581, in parse
    with as_handle(handle, mode) as fp:
  File "/usr/lib/python2.7/contextlib.py", line 17, in __enter__
    return self.gen.next()
  File "/usr/local/lib/python2.7/dist-packages/Bio/File.py", line 88, in as_handle
    with open(handleish, mode, **kwargs) as fp:
IOError: [Errno 2] No such file or directory: './reconstruction_data/SR_Thornton/ER/input_AR_MR.fasta'
